<?xml version="1.0"?>
<robot name="my_robot">

<gazebo>
  <plugin name="gazebo_ros_control" filename="libgazebo_ros_control.so"/>
  <robotNamespace>/my_robot</robotNamespace>
      <robotSimType>gazebo_ros_control/DefaultRobotHWSim</robotSimType>
</gazebo>


<gazebo reference="base_link"> 
<mu1>0.9</mu1>
    <mu2>0.9</mu2>
    <material>Gazebo/Blue</material> 
</gazebo>

<gazebo reference="wheel_link">
  <mu1>0.9</mu1>
    <mu2>0.9</mu2>
    <material>Gazebo/Red</material>
</gazebo>


  <!-- Base link -->
  <link name="base_link">

    <collision>
      <geometry>
        <box size="1 1 0.1"/>
      </geometry>
    </collision>

    <visual>
      <geometry>
        <box size="1 1 0.1"/>
      </geometry>
      <origin xyz="0 0 0" rpy="0 0 0"/>
      <material name="blue">
        <color rgba="0 0 1 1"/>
      </material>
    </visual>

      <inertial>
        <mass value="1.0"/>
        <origin xyz="0 0 0" rpy="0 0 0"/>
        <inertia ixx="0.01" ixy="0.0" ixz="0.0" iyy="0.01" iyz="0.0" izz="0.01"/>
    </inertial>

  </link>

  <!-- A wheel -->
  <link name="wheel_link">

  <collision>
    <geometry>
      <cylinder radius="0.2" length="0.1"/>
    </geometry>
  </collision>

    <visual>
      <geometry>
        <cylinder length="0.1" radius="0.2"/>
      </geometry>
      <origin xyz="0 0 0" rpy="1.5708 0 0"/>
      <material name="black">
        <color rgba="0 0 0 1"/>
      </material>
    </visual>

    <inertial>
    <mass value="0.5"/>
    <origin xyz="0 0 0" rpy="0 0 0"/>
    <inertia ixx="0.005" ixy="0.0" ixz="0.0" iyy="0.005" iyz="0.0" izz="0.005"/>
  </inertial>

  </link>

  <!-- Joint connecting wheel to base -->
  <!-- <joint name="base_to_wheel" type="continuous">
    <parent link="base_link"/>
    <child link="wheel_link"/>
    <origin xyz="0.5 0 0" rpy="0 0 0"/>
    <axis xyz="0 0 1"/>
  </joint> -->


<joint name="wheel_joint" type="revolute">
    <parent link="base_link"/>
    <child link="wheel_link"/>
    <origin xyz="0.5 0 0" rpy="0 0 0"/>
    <axis xyz="0 0 1"/>
    <limit effort="10" velocity="10" lower="-3.14" upper="3.14"/>
</joint>




<transmission name="wheel_trans">
    <type>transmission_interface/SimpleTransmission</type>
    <joint name="wheel_joint">
      <hardwareInterface>hardware_interface/EffortJointInterface</hardwareInterface>
    </joint>
    
    <actuator name="wheel_motor">
      <hardwareInterface>hardware_interface/EffortJointInterface</hardwareInterface>
      <mechanicalReduction>1</mechanicalReduction>
    </actuator>
</transmission>


</robot>
